Workbook

Sheet AI
A1: number | B1: call_name | C1: transcription | D1: default_call_week | E1: id_item_set | F1: item_set_created_at | G1: item_set_updated_at | H1: month_of_processing | I1: real_file_duration | J1: call_parts_count | K1: call_date | L1: call_duration | M1: call_id | N1: call_phone | O1: call_source | P1: call_time | Q1: call_type | R1: call_week | S1: contact_id | T1: contact_name | U1: contact_type | V1: lead_created_at | W1: lead_id | X1: lead_name | Y1: lead_pipeline | Z1: lead_status | AA1: lead_url | AB1: user_id | AC1: user_name | AD1: score_0 | AE1: reason_0 | AF1: quote_0 | AG1: score_1 | AH1: reason_1 | AI1: quote_1 | AJ1: score_2 | AK1: reason_2 | AL1: quote_2 | AM1: score_3 | AN1: reason_3 | AO1: quote_3 | AP1: score_4 | AQ1: reason_4 | AR1: quote_4 | AS1: score_5 | AT1: reason_5 | AU1: quote_5 | AV1: score_6 | AW1: reason_6 | AX1: quote_6 | AY1: score_7 | AZ1: reason_7 | BA1: quote_7 | BB1: score_8 | BC1: reason_8 | BD1: quote_8 | BE1: score_9 | BF1: reason_9 | BG1: quote_9 | BH1: score_10 | BI1: reason_10 | BJ1: quote_10 | BK1: score_11 | BL1: reason_11 | BM1: quote_11 | BN1: score_12 | BO1: reason_12 | BP1: quote_12 | BQ1: score_13 | BR1: reason_13 | BS1: quote_13 | BT1: score_14 | BU1: reason_14 | BV1: quote_14 | BW1: score_15 | BX1: reason_15 | BY1: quote_15 | BZ1: score_16 | CA1: reason_16 | CB1: quote_16 | CC1: score_17 | CD1: reason_17 | CE1: quote_17 | CF1: score_18 | CG1: reason_18 | CH1: quote_18 | CI1: score_19 | CJ1: reason_19 | CK1: quote_19 | CL1: score_20 | CM1: reason_20 | CN1: quote_20 | CO1: score_21 | CP1: reason_21 | CQ1: quote_21 | CR1: score_22 | CS1: reason_22 | CT1: quote_22 | CU1: score_23 | CV1: reason_23 | CW1: quote_23 | CX1: score_24 | CY1: reason_24 | CZ1: quote_24 | DA1: score_25 | DB1: reason_25 | DC1: quote_25 | DD1: score_26 | DE1: reason_26 | DF1: quote_26 | DG1: score_27 | DH1: reason_27 | DI1: quote_27 | DJ1: score_28 | DK1: reason_28 | DL1: quote_28 | DM1: score_29 | DN1: reason_29 | DO1: quote_29 | DP1: score_30 | DQ1: reason_30 | DR1: quote_30 | DS1: score_31 | DT1: reason_31 | DU1: quote_31 | EH1: total_score | EI1: total_score_mandatory | EJ1: duration_min | EK1: group_score_1 | EL1: group_score_1_mandatory | EO1: field_866934
K2: CRM | AD2: Приветствие | AJ2: Снятие первичного волнения | AP2: Презентация предстоящего термина | AY2: Отправка материалов | BH2: Вопросы и возражения Клиента | BQ2: Следующие шаги | BW2: Завершение разговора | CI2: Стандарты общения | CO2: Критические ошибки | CX2: Экспертный блок | DD2: Рекомендации | DP2: Фильтры
A3: № | B3: Call file name | C3: Transcription | D3: Week of the call | E3: Item Set ID | F3: Item Set Created At | G3: Date of Analyze | H3: Month of Analyze | I3: Real File Duration | J3: количество частей | K3: Дата звонка | L3: Длительность | M3: ID звонка | N3: Телефон | O3: Источник | P3: Время звонка | Q3: Тип звонка | R3: Номер недели | S3: ID контакта | T3: ФИО контакта | U3: Тип контакта | V3: Дата создания сделки | W3: ID сделки | X3: Название сделки | Y3: Воронка сделки | Z3: Этап сделки | AA3: Ссылка на сделку | AB3: ID менеджера | AC3: ФИО менеджера | AD3: 1. Приветствие и представление менеджера | AE3: 1. Приветствие и представление менеджера – Reason | AF3: 1. Приветствие и представление менеджера – Quote | AG3: 2. Программирование разговора | AH3: 2. Программирование разговора – Reason | AI3: 2. Программирование разговора – Quote | AJ3: 3. Уточнение эмоционального состояния клиента перед термином | AK3: 3. Уточнение эмоционального состояния клиента перед термином – Reason | AL3: 3. Уточнение эмоционального состояния клиента перед термином – Quote | AM3: 4. Снятие волнения и поддержка клиента | AN3: 4. Снятие волнения и поддержка клиента – Reason | AO3: 4. Снятие волнения и поддержка клиента – Quote | AP3: 5. Объяснение формата встречи с бератером | AQ3: 5. Объяснение формата встречи с бератером – Reason | AR3: 5. Объяснение формата встречи с бератером – Quote | AS3: 6. Объяснение типичных вопросов бератера | AT3: 6. Объяснение типичных вопросов бератера – Reason | AU3: 6. Объяснение типичных вопросов бератера – Quote | AV3: 7. Снижение страха перед термином | AW3: 7. Снижение страха перед термином – Reason | AX3: 7. Снижение страха перед термином – Quote | AY3: 8. Отправка памятки для подготовки к термину | AZ3: 8. Отправка памятки для подготовки к термину – Reason | BA3: 8. Отправка памятки для подготовки к термину – Quote | BB3: 9. Объяснение содержания памятки | BC3: 9. Объяснение содержания памятки – Reason | BD3: 9. Объяснение содержания памятки – Quote | BE3: 10. Отправка тренажёра для подготовки | BF3: 10. Отправка тренажёра для подготовки – Reason | BG3: 10. Отправка тренажёра для подготовки – Quote | BH3: 11. Теги возражений | BI3: 11. Теги возражений – Reason | BJ3: 11. Теги возражений – Quote | BK3: 12. Корректность отработки возражений Клиента | BL3: 12. Корректность отработки возражений Клиента – Reason | BM3: 12. Корректность отработки возражений Клиента – Quote | BN3: 13. Вопросы Клиента | BO3: 13. Вопросы Клиента – Reason | BP3: 13. Вопросы Клиента – Quote | BQ3: 14. Договорённость о следующем контакте | BR3: 14. Договорённость о следующем контакте – Reason | BS3: 14. Договорённость о следующем контакте – Quote | BT3: 15. Открытый канал связи и поддержка Клиента | BU3: 15. Открытый канал связи и поддержка Клиента – Reason | BV3: 15. Открытый канал связи и поддержка Клиента – Quote | BW3: 16. Проверка уверенности Клиента после разговора | BX3: 16. Проверка уверенности Клиента после разговора – Reason | BY3: 16. Проверка уверенности Клиента после разговора – Quote | BZ3: 17. Объяснение процесса после успешного термина | CA3: 17. Объяснение процесса после успешного термина – Reason | CB3: 17. Объяснение процесса после успешного термина – Quote | CC3: 18. Инструкция на случай отказа в финансировании | CD3: 18. Инструкция на случай отказа в финансировании – Reason | CE3: 18. Инструкция на случай отказа в финансировании – Quote | CF3: 19. Сопровождение Клиента после термина | CG3: 19. Сопровождение Клиента после термина – Reason | CH3: 19. Сопровождение Клиента после термина – Quote | CI3: 20. Общая доброжелательность и вежливость Продавца | CJ3: 20. Общая доброжелательность и вежливость Продавца – Reason | CK3: 20. Общая доброжелательность и вежливость Продавца – Quote | CL3: 21. Продавец использовал активное слушание и отзеркаливание Клиента | CM3: 21. Продавец использовал активное слушание и отзеркаливание Клиента – Reason | CN3: 21. Продавец использовал активное слушание и отзеркаливание Клиента – Quote | CO3: 22. Критические ошибки с точки зрения компании | CP3: 22. Критические ошибки с точки зрения компании – Reason | CQ3: 22. Критические ошибки с точки зрения компании – Quote | CR3: 23. Критические ошибки с точки зрения клиента | CS3: 23. Критические ошибки с точки зрения клиента – Reason | CT3: 23. Критические ошибки с точки зрения клиента – Quote | CU3: 24. Критические ошибки с точки зрения закона | CV3: 24. Критические ошибки с точки зрения закона – Reason | CW3: 24. Критические ошибки с точки зрения закона – Quote | CX3: 25. Структура звонка: фактический скрипт, который применил Продавец | CY3: 25. Структура звонка: фактический скрипт, который применил Продавец – Reason | CZ3: 25. Структура звонка: фактический скрипт, который применил Продавец – Quote | DA3: 26. Потеря клиента на этапе закрытия | DB3: 26. Потеря клиента на этапе закрытия – Reason | DC3: 26. Потеря клиента на этапе закрытия – Quote | DD3: 27. Краткое резюме звонка | DE3: 27. Краткое резюме звонка – Reason | DF3: 27. Краткое резюме звонка – Quote | DG3: 28. Рекомендации Продавцу: зоны роста | DH3: 28. Рекомендации Продавцу: зоны роста – Reason | DI3: 28. Рекомендации Продавцу: зоны роста – Quote | DJ3: 29. Рекомендации Продавцу: лучшие практики | DK3: 29. Рекомендации Продавцу: лучшие практики – Reason | DL3: 29. Рекомендации Продавцу: лучшие практики – Quote | DM3: 30. Портрет клиента | DN3: 30. Портрет клиента – Reason | DO3: 30. Портрет клиента – Quote | DP3: 31. Сбой или прерывание разговора | DQ3: 31. Сбой или прерывание разговора – Reason | DR3: 31. Сбой или прерывание разговора – Quote | DS3: 32. Полезный звонок | DT3: 32. Полезный звонок – Reason | DU3: 32. Полезный звонок – Quote | DV3: =IFERROR(SUM(AD2,AG2)/COUNT(AD2,AG2),"Приветствие") -> Приветствие | DW3: =IFERROR(SUM(AJ2,AM2)/COUNT(AJ2,AM2),"Снятие первичного волнения") -> Снятие первичного волнения | DX3: =IFERROR(SUM(AP2,AS2,AV2)/COUNT(AP2,AS2,AV2),"Презентация предстоящего термина") -> Презентация предстоящего термина | DY3: =IFERROR(SUM(AY2,BB2,BE2)/COUNT(AY2,BB2,BE2),"Отправка материалов") -> Отправка материалов | DZ3: =IFERROR(SUM(BH2,BK2,BN2)/COUNT(BH2,BK2,BN2),"Вопросы и возражения Клиента") -> Вопросы и возражения Клиента | EA3: =IFERROR(SUM(BQ2,BT2)/COUNT(BQ2,BT2),"Следующие шаги") -> Следующие шаги | EB3: =IFERROR(SUM(BW2,BZ2,CC2,CF2)/COUNT(BW2,BZ2,CC2,CF2),"Завершение разговора") -> Завершение разговора | EC3: =IFERROR(SUM(CI2,CL2)/COUNT(CI2,CL2),"Стандарты общения") -> Стандарты общения | ED3: =IFERROR(SUM(CO2,CR2,CU2)/COUNT(CO2,CR2,CU2),"Критические ошибки") -> Критические ошибки | EE3: =IFERROR(SUM(CX2,DA2)/COUNT(CX2,DA2),"Экспертный блок") -> Экспертный блок | EF3: =IFERROR(SUM(DD2,DG2,DJ2,DM2)/COUNT(DD2,DG2,DJ2,DM2),"Рекомендации") -> Рекомендации | EG3: =IFERROR(SUM(DP2,DS2)/COUNT(DP2,DS2),"Фильтры") -> Фильтры | EH3: total_score | EI3: total_score_mandatory | EJ3: duration_min | EK3: group_score_1 | EL3: group_score_1_mandatory | EM3: Итоговый процент за звонок | EN3: Длительность (мин) | EO3: Категория
A4: 4 | B4: 172422187_1887961834_d98a01 | C4: https://docs.google.com/document/d/1iXoK0aGGJsISwZGbnQRnKIw9zvdErJqWrIckgLxefJk/edit?usp=drivesdk | D4: 2026-03-09 - 2026-03-15 | E4: 54506 | F4: 2026-03-10 18:47:10 | G4: 2026-03-10 18:56:16 | H4: 2026.03 | I4: 563.544 | J4: 1 | K4: 2026-03-09 | L4: 564 | M4: 172422187_1887961834 | N4: +4915115887174, Статус: Разговор состоялся | O4: CallGear | P4: 16:29:09+01:00 | Q4: Исходящий | R4: 11 | S4: 20567538 | T4: Lavrentieva Viktoriia | U4: Контакт | V4: 2026-02-18T17:25:15+01:00 | W4: 18053858 | X4: Автосделка: New lead form Typeform 1769898488 | Y4: Бух Бератер | Z4: Доведение | AA4: https://sternmeister.kommo.com/leads/detail/18053858 | AB4: 14817967 | AC4: Кристина Никоненко | AD4: 1 | AE4: Менеджер поприветствовала клиента, представилась и назвала компанию. | AF4: [00:00:00.031] – Продавец – Виктория, добрый вечер. Здравствуйте. Меня зовут Кристина, я менеджер сопровождения компании Шторммастеры. | AG4: 1 | AH4: Менеджер обозначила цель звонка (узнать про термин), предложила обсудить дальнейшие шаги и подготовку к термину. Также уточнила, есть ли у клиента 5-10 минут для разговора. | AI4: [00:00:00.031] – Продавец – Виктория, добрый вечер. Здравствуйте. Меня зовут Кристина, я менеджер сопровождения компании Шторммастеры. Звоню узнать, как у вас обстоят с термином. Удалось ли вам новый термин оформить у бирайтера?, [00:00:19.512] – Продавец – Я вас поздравляю. Подскажите, пожалуйста, есть ли у вас буквально 5-10 минут для того, чтобы мы дальнейшие шаги, например, обсудили, подготовку к термину? | AJ4: 1 | AK4: Менеджер прямо спросил клиента о его эмоциональном состоянии и наличии волнения перед предстоящим термином. | AL4: [00:01:07.130] – Продавец – Подскажите, пожалуйста, как себя в целом чувствуете? Есть ли волнение перед предстоящим термином? | AM4: 1 | AN4: Клиент сказал, что пока не испытывает волнения. Менеджер одобрила такой настрой и перешла к объяснениям, подразумевая, что это поможет избежать волнения в будущем. | AO4: [00:01:10.520] – Клиент – Пока что нет. [00:01:13.238] – Продавец – Это хороший настрой. В любом случае, главное, что смысл встреч понимаете, какие вопросы будет бирайтер задавать: почему именно данные курсы выбрали, как это поможет вам выйти на рынок труда, почему выбрали именно бухгалтерию, знаете ли вы содержание курса, сколько он длится. То есть все-таки стандартные вопросы будет задавать бирайтер на встрече с вами. | AP4: 1 | AQ4: Менеджер объяснила, что бератер будет задавать стандартные вопросы, касающиеся выбора курса и планов после обучения, что указывает на роль бератера как проверяющего целесообразность. | AR4: [00:01:13.238] – Продавец – Это хороший настрой. В любом случае, главное, что смысл встреч понимаете, какие вопросы будет бирайтер задавать: почему именно данные курсы выбрали, как это поможет вам выйти на рынок труда, почему выбрали именно бухгалтерию, знаете ли вы содержание курса, сколько он длится. То есть все-таки стандартные вопросы будет задавать бирайтер на встрече с вами. | AS4: 1 | AT4: Менеджер привела примеры вопросов, которые бератер обычно задает, касающиеся мотивации выбора курса, его содержания и планов клиента. | AU4: [00:01:13.238] – Продавец – В любом случае, главное, что смысл встреч понимаете, какие вопросы будет бирайтер задавать: почему именно данные курсы выбрали, как это поможет вам выйти на рынок труда, почему выбрали именно бухгалтерию, знаете ли вы содержание курса, сколько он длится. То есть все-таки стандартные вопросы будет задавать бирайтер на встрече с вами. | AV4: 1 | AW4: Менеджер снизила страх, предложив тренировку произношения и понимания логики ответов через бота, а также отметив, что можно говорить простыми фразами и не нужно ничего зубрить. | AX4: [00:02:04.260] – Продавец – И можете прям по памятке почитать в спокойном для себя темпе. Время у нас много, не нужно ничего зубрить, главное понять логику ответов и несколько раз проговорить ключевые фразы. И как раз можно потренировать произношение по памятке и аудирование за счет бота. Это вам поможет говорить уверенно, четко и пусть даже простыми фразами., [00:02:32.600] – Клиент – Да, мне лучше простыми фразами, я потом запутываюсь. | AY4: 0 | AZ4: Менеджер не сообщила об отправке памятки, но спросила, присылали ли ее коллеги. Памятка уже была у клиента, но менеджер не предложила ее продублировать или отправить еще раз для удобства. | BA4: [00:00:31.466] – Продавец – Замечательно. Подскажите, пожалуйста, помните, возможно, прислали ли вам мои коллеги памятку по вопросам, которые обычно берут?, [00:00:40.480] – Клиент – Да, есть. | BB4: 1 | BC4: Менеджер не объяснила содержание памятки, но клиент подтвердил, что она у него есть и он ее "тогда смотрел" и пересмотрит позже. Менеджер упомянула, что по памятке можно "почитать в спокойном для себя темпе", и это поможет "понять логику ответов". | BD4: [00:00:44.426] – Клиент – Ну, я тогда смотрела, когда ходила первый раз на встречу. Вот поэтому я еще пересмотрю перед тем, как идти. Ну, просто это 24 марта, я все забуду, я поэтому посмотрю., [00:02:04.260] – Продавец – И можете прям по памятке почитать в спокойном для себя темпе. Время у нас много, не нужно ничего зубрить, главное понять логику ответов и несколько раз проговорить ключевые фразы. | BE4: 1 | BF4: Менеджер сообщила об отправке бота-тренажера G5 на e-mail и объяснила, как он поможет тренировать произношение и аудирование. | BG4: [00:01:48.620] – Клиент – Нет. [00:01:50.240] – Продавец – Я вам его тогда отправлю на e-mail. Он работает достаточно... Включить?, [00:02:04.260] – Продавец – И можете прям по памятке почитать в спокойном для себя темпе. Время у нас много, не нужно ничего зубрить, главное понять логику ответов и несколько раз проговорить ключевые фразы. И как раз можно потренировать произношение по памятке и аудирование за счет бота. Это вам поможет говорить уверенно, четко и пусть даже простыми фразами. | BH4: Тегов нет. | BI4: Клиент не озвучивал явных возражений или сомнений по отношению к курсу или процессу, только небольшое беспокойство по поводу того, что забудет информацию из памятки из-за срока до термина и медлительности Job Center. | BJ4: [00:00:44.426] – Клиент – Ну, я тогда смотрела, когда ходила первый раз на встречу. Вот поэтому я еще пересмотрю перед тем, как идти. Ну, просто это 24 марта, я все забуду, я поэтому посмотрю., [00:05:10.000] – Клиент – Ой, я не думаю, что 30 марта. У меня такой же центр, они очень медленные. Если у меня 24-го только будет термин, то вряд ли, говорю сразу. | BL4: Клиент не озвучивал явных возражений или сомнений, которые требовали бы отработки. Единственное, что можно отнести к сомнениям, – это беспокойство о том, что клиент забудет информацию к дате термина, на что Менеджер отреагировала понимающе, но без конкретного предложения, которое могло бы снять это сомнение. Также клиент выразил сомнение в своевременном начале курса из-за медлительности Job Center, на что Менеджер предложила запасные варианты. | BM4: [00:00:44.426] – Клиент – Ну, я тогда смотрела, когда ходила первый раз на встречу. Вот поэтому я еще пересмотрю перед тем, как идти. Ну, просто это 24 марта, я все забуду, я поэтому посмотрю., [00:01:00.660] – Продавец – Я понимаю, да, когда оно далеко. Да. | BN4: 1 | BO4: Клиент задавал несколько вопросов, и Менеджер корректно на них ответила. Были вопросы по поводу бота ('как его включить?') и по поводу даты ангибота/следующего курса. | BP4: [00:01:57.800] – Клиент – Ну да, как его включить?, [00:02:00.560] – Продавец – А просто его запускаете, он открывается в браузере., [00:05:00.740] – Клиент – А когда следующий курс? В мае или когда вы говорили? | BQ4: 1 | BR4: Менеджер договорилась о следующем звонке с клиентом на 16 число в 12:30, чтобы ответить на возможные вопросы. | BS4: [00:03:12.800] – Клиент – Давайте, может, позже немножко, может, числа 16-го., [00:03:18.020] – Продавец – Давайте попробуем хорошо 16-го тогда. Во 2-й, в 1-й половине, как вам будет удобно?, [00:03:39.800] – Клиент – Сейчас я подумаю. Лучше где-то в 12:30. | BT4: 1 | BU4: Менеджер явно сообщила клиенту, что он может писать, если появятся вопросы до следующего звонка. | BV4: [00:09:13.800] – Продавец – Хорошо, если будут вопросы, то тоже пишите обязательно, буду вам отправлю. | BW4: 1 | BX4: Менеджер прямо спросила клиента о том, как он себя чувствует после разговора, стало ли ему понятнее и появилась ли уверенность. | BY4: [00:03:47.460] – Продавец – Я так и поставлю, у меня сейчас расписание свободно. Подскажите, пожалуйста, как вы себя чувствуете после нашего разговора? Более понятно, может быть, появилась какая-то уверенность в предстоящем вашем решении? | BZ4: 1 | CA4: Менеджер подробно объяснила дальнейший процесс после успешного термина, включая передачу документов в агентство РБА, назначение нового термина и важность запроса на ускорение этого процесса. | CB4: [00:04:18.000] – Продавец – Я вас поняла. К любым результатам действительно нужно быть готовым. И по поводу результатов хотелось бы проговорить еще также важный момент. Если термин в Job Center пройдет успешно, ваши документы должны передать в агентство РБА. Обиратель вам об этом скажет. Далее они назначают новый термин уже. И тут нужно попросить сделать это как можно быстрее, чтобы не пропустить начало потока. | CC4: 1 | CD4: Менеджер дала четкие инструкции на случай отказа в финансировании, подчеркнув важность выяснения причины и возможности повлиять на ситуацию. | CE4: [00:07:07.780] – Продавец – И также, если вдруг, если по каким-либо причинам бирайтер не одобрит финансирование нашего курса, хотя у вас достаточно хороший шанс на получение финансирования, однако хочу отметить, что вам нужно во время термина выяснить причину, спросить, как он видит ваше развитие и чего, по его мнению, вам не хватает, чтобы получить финансирование. То есть важность термина с полным пониманием, какое решение принято и как можно на это повлиять, если потребуется. | CF4: 0 | CG4: Менеджер не сообщила о том, что свяжется с клиентом после термина для обсуждения дальнейших действий. Была договоренность о звонке до термина, но не после. | CI4: 1 | CJ4: Продавец обращалась к клиенту по имени ("Виктория", [00:00:00.031]), использовала вежливые слова ("здравствуйте", "пожалуйста", "спасибо"). Общалась уважительно и доброжелательно, подстраивая тон под спокойное состояние клиента. | CK4: [00:00:00.031] – Продавец – Виктория, добрый вечер. Здравствуйте. Меня зовут Кристина, я менеджер сопровождения компании Шторммастеры., [00:00:19.512] – Продавец – Я вас поздравляю. Подскажите, пожалуйста, есть ли у вас буквально 5-10 минут для того, чтобы мы дальнейшие шаги, например, обсудили, подготовку к термину?, [00:09:18.720] – Клиент – Спасибо большое. | CL4: 1 | CM4: Продавец активно слушала клиента, реагировала на его реплики ("Я понимаю", "Я вас поняла"), поддерживала диалог и даже перефразировала ("Мне главное, чтобы сертификат котировался в Германии. - Я так поняла, что он официальный.") | CN4: [00:01:00.660] – Продавец – Я понимаю, да, когда оно далеко. Да., [00:02:38.220] – Продавец – Ну, я вас прекрасно понимаю., [00:04:18.000] – Продавец – Я вас поняла. К любым результатам действительно нужно быть готовым., [00:08:41.740] – Продавец – Я так поняла, что он официальный. | CO4: 1 | CP4: Критических ошибок с точки зрения компании не было. Продавец не высказывалась негативно, не отговаривала клиента, не дезинформировала. Разговор завершился с фиксацией следующего шага - запланированного звонка. | CQ4: [00:09:12.640] – Клиент – Хорошо, да., [00:09:13.800] – Продавец – Хорошо, если будут вопросы, то тоже пишите обязательно, буду вам отправлю. | CR4: 1 | CS4: Продавец не допустила критических ошибок. Информация, касающаяся курса и процессов, была корректной. Поведение было уважительным, ответы ясные. Менеджер грамотно пояснила статус сертификата, что он "официальный" и "государство одобрило". | CT4: [00:08:45.240] – Клиент – Да, это официальное. [00:08:46.000] – Продавец – Государство одобрило, то есть оно финансирует именно то, что нужно для трудоустройства вам. Другого оно финансировать не будет. Кто бы этого не хотел, может быть, и к лучшему, зато все максимально официально. | CU4: 1 | CV4: Критических нарушений с точки зрения закона не зафиксировано. Продавец не давала ложных гарантий, не разглашала внутреннюю информацию и корректно комментировала статус сертификации, не заявляя о наличии AZAV, но говоря об официальности и одобрении государством. | CW4: [00:08:46.000] – Продавец – Государство одобрило, то есть оно финансирует именно то, что нужно для трудоустройства вам. Другого оно финансировать не будет. Кто бы этого не хотел, может быть, и к лучшему, зато все максимально официально. | CX4: 1 | CY4: А) Фактический скрипт:1. Приветствие и представление: Менеджер поздоровалась, представилась и назвала компанию. [00:00:00.031]2. Уточнение статуса термина: Менеджер спросила, оформлен ли новый термин. [00:00:06.666]3. Программирование разговора: Спросила об удобстве 5-10 минут для обсуждения дальнейших шагов. [00:00:19.512]4. Проверка наличия памятки: Уточнила, получал ли клиент памятку. [00:00:31.466]5. Проверка эмоционального состояния: Спросила о волнении перед термином. [00:01:07.130]6. Объяснение формата встречи с бератером: Рассказала о стандартных вопросах. [00:01:13.238]7. Предложение тренажера: Спросила, отправляли ли бота G5, и при отрицательном ответе предложила отправить. [00:01:48.620]8. Ценность тренажера: Объяснила, как бот поможет в подготовке. [00:02:04.260]9. Планирование следующего контакта: Предложила созвониться, чтобы ответить на вопросы. [00:02:45.380]10. Уточнение после разговора: Спросила о настроении клиента после звонка. [00:03:47.460]11. Объяснение процесса после успешного термина: Рассказала о передаче документов и важности быстрого назначения следующего термина. [00:04:18.000]12. Уточнение даты ангибота: Спросила, на какую дату был ангибот. [00:04:50.760]13. Инструкция на случай отказа: Рассказала, что делать, если бератер не одобрит финансирование. [00:07:07.780]14. Завершение разговора: Договоренность о следующем звонке и предложении писать с вопросами. [00:09:12.640]Б) Особенности скрипта: Продавец довольно последовательно шла по скрипту, охватывая ключевые моменты подготовки к термину. Нестандартным шагом можно назвать предложение бота G5. Пропущено было активное предложение отправить памятку повторно, хотя клиент упоминал, что пересмотрит её.В) Элементы скрипта сработали: Клиент подтвердил наличие термина, согласился на разговор, проявил интерес к боту G5, согласился на следующий звонок, задавал уточняющие вопросы по срокам и документам.Г) Элементы не сработали: Возможно, недостаточно активно была отработана фраза клиента о том, что "она все забудет", на что менеджер просто ответила: "Я понимаю, да, когда оно далеко". | CZ4: [00:00:00.031] – Продавец – Виктория, добрый вечер. Здравствуйте. Меня зовут Кристина, я менеджер сопровождения компании Шторммастеры., [00:00:19.512] – Продавец – Я вас поздравляю. Подскажите, пожалуйста, есть ли у вас буквально 5-10 минут для того, чтобы мы дальнейшие шаги, например, обсудили, подготовку к термину?, [00:00:31.466] – Продавец – Замечательно. Подскажите, пожалуйста, помните, возможно, прислали ли вам мои коллеги памятку по вопросам, которые обычно берут?, [00:01:07.130] – Продавец – Подскажите, пожалуйста, как себя в целом чувствуете? Есть ли волнение перед предстоящим термином?, [00:01:13.238] – Продавец – В любом случае, главное, что смысл встреч понимаете, какие вопросы будет бирайтер задавать: почему именно данные курсы выбрали, как это поможет вам выйти на рынок труда, почему выбрали именно бухгалтерию, знаете ли вы содержание курса, сколько он длится., [00:01:48.620] – Клиент – Нет. [00:01:50.240] – Продавец – Я вам его тогда отправлю на e-mail., [00:02:04.260] – Продавец – И можете прям по памятке почитать в спокойном для себя темпе. , [00:02:45.380] – Продавец – Подскажите, пожалуйста, также могу с вами позвонить где-нибудь, например, 12-го числа, 13-го числа, для того, чтобы, если у вас появятся вопросы по памятке, либо вообще в целом, может быть, про обучение какие-то вопросы появятся, я на них отвечу, в какое время вам будет удобно?, [00:03:47.460] – Продавец – Подскажите, пожалуйста, как вы себя чувствуете после нашего разговора? Более понятно, может быть, появилась какая-то уверенность в предстоящем вашем решении?, [00:04:18.000] – Продавец – Я вас поняла. К любым результатам действительно нужно быть готовым. И по поводу результатов хотелось бы проговорить еще также важный момент. Если термин в Job Center пройдет успешно, ваши документы должны передать в агентство РБА., [00:04:50.760] – Клиент – Сейчас скажу., [00:07:07.780] – Продавец – И также, если вдруг, если по каким-либо причинам бирайтер не одобрит финансирование нашего курса, хотя у вас достаточно хороший шанс на получение финансирования, однако хочу отметить, что вам нужно во время термина выяснить причину, спросить, как он видит ваше развитие и чего, по его мнению, вам не хватает, чтобы получить финансирование., [00:09:12.640] – Клиент – Хорошо, да. [00:09:13.800] – Продавец – Хорошо, если будут вопросы, то тоже пишите обязательно, буду вам отправлю. | DA4: 1 | DB4: Разговор завершился позитивно, с конкретной договоренностью о следующем шаге: запланирован звонок на 16 число в 12:30. Клиент проявил готовность к последующим действиям. | DC4: [00:09:12.640] – Клиент – Хорошо, да., [00:09:13.800] – Продавец – Хорошо, если будут вопросы, то тоже пишите обязательно, буду вам отправлю., [00:09:20.020] – Продавец – До свидания., [00:09:21.040] – Клиент – До свидания.. | DD4: Резюме | DE4: А) Содержание звонка: Звонок был посвящен подготовке клиента к предстоящему термину в Job Center. Были затронуты темы: подтверждение даты термина, обсуждение возможных вопросов бератера, важность понимания логики ответов, предложение бота-тренажера для практики, инструкции на случай успешного/неуспешного прохождения термина, а также планирование следующего звонка для ответа на вопросы клиента. Мотивация клиента, презентация курса или этап оплаты не обсуждались, так как это был звонок сопровождения.Б) Реакция Клиента: Клиент была спокойна и в целом позитивно настроена. Она подтвердила наличие термина, выразила согласие на предложенный план подготовки (обсуждение, бот, следующий звонок) и задала уточняющие вопросы по срокам и документам. Не было выражено явных сомнений или негатива.В) Достигнутые договорённости: Были зафиксированы следующие шаги: отправка бота-тренажера на e-mail клиента, а также следующий звонок 16 марта в 12:30 для обсуждения вопросов. Продавец зафиксировала следующий шаг. | DG4: Рекомендация | DH4: 1. Фраза Продавца: "Я понимаю, да, когда оно далеко". Контекст: Клиент сказала, что все забудет к 24 марта, потому что это долго. Продавец отреагировала этой фразой. Как следовало сказать: "Я прекрасно понимаю, что так бывает. Именно поэтому у нас есть памятка и бот-тренажер, которые можно использовать ближе к дате термина, чтобы освежить память и быть уверенной в ответах. Мы также созвонимся с вами ближе к дате, чтобы еще раз все проговорить." Ожидаемый эффект: Это позволило бы сразу же снять беспокойство клиента, подкрепить ценность предложенных инструментов и подтвердить дальнейшую поддержку, усилив уверенность клиента. 2. Фраза Продавца: Отсутствие активного предложения продублировать памятку. Контекст: Продавец спросила, присылали ли коллеги памятку, клиент ответила "да, есть", но также сказала, что "тогда смотрела" и "еще пересмотрит перед тем, как идти". Как следовало сказать: "Отлично, что памятка у вас есть. Я могу продублировать ее вам на почту вместе с ботом, чтобы она точно была под рукой, когда вы решите ее пересмотреть." Ожидаемый эффект: Это показало бы дополнительную заботу о клиенте, гарантировало бы наличие актуальной версии памятки и упростило бы для клиента доступ к ней, что также могло бы снизить беспокойство о том, что она "все забудет". | DI4: [00:00:44.426] – Клиент – Ну, я тогда смотрела, когда ходила первый раз на встречу. Вот поэтому я еще пересмотрю перед тем, как идти. Ну, просто это 24 марта, я все забуду, я поэтому посмотрю., [00:01:00.660] – Продавец – Я понимаю, да, когда оно далеко. Да. | DJ4: Рекомендация | DK4: 1. Фраза Продавца: "Я вам его тогда отправлю на e-mail. Он работает достаточно... Включить? ... И можете прям по памятке почитать в спокойном для себя темпе. ... И как раз можно потренировать произношение по памятке и аудирование за счет бота. Это вам поможет говорить уверенно, четко и пусть даже простыми фразами." Контекст: Клиент не знала о боте G5. Продавец предложила его отправить и подробно объяснила его пользу. Почему это сработало: Продавец предложила конкретный инструмент для решения возможной проблемы (страх перед экзаменом, плохой немецкий), подробно объяснила его функционал и преимущества, а также сняла возможное опасение клиента о сложности ("пусть даже простыми фразами"). Техника: Презентация решения потребностей (Feature-Advantage-Benefit), снижение барьеров. Тип практики: Массовая техника. 2. Фраза Продавца: "...вам нужно во время термина выяснить причину, спросить, как он видит ваше развитие и чего, по его мнению, вам не хватает, чтобы получить финансирование. То есть важность термина с полным пониманием, какое решение принято и как можно на это повлиять, если потребуется. К примеру, бывали такие моменты, что бирайтер отправляет на работу... В таком случае можно договориться с бирайтером о том, что на повторный термин вы ему принесете отклики... Если будут в виде отказа, то уже можно будет еще раз повторно рассмотреть обучение." Контекст: Продавец дала инструкцию, что делать в случае отказа в финансировании. Почему это сработало: Продавец не только подготовила клиента к возможному негативному исходу, но и предложила конкретный, пошаговый план действий для преодоления препятствия, придавая клиенту уверенность в том, что даже в случае отказа есть пути решения. Техника: Работа с возражениями на опережение, предоставление алгоритма действий, усиление позиции клиента. Тип практики: Массовая техника. | DL4: [00:01:50.240] – Продавец – Я вам его тогда отправлю на e-mail. Он работает достаточно... Включить?, [00:02:04.260] – Продавец – И можете прям по памятке почитать в спокойном для себя темпе. Время у нас много, не нужно ничего зубрить, главное понять логику ответов и несколько раз проговорить ключевые фразы. И как раз можно потренировать произношение по памятке и аудирование за счет бота. Это вам поможет говорить уверенно, четко и пусть даже простыми фразами., [00:07:07.780] – Продавец – И также, если вдруг, если по каким-либо причинам бирайтер не одобрит финансирование нашего курса, хотя у вас достаточно хороший шанс на получение финансирования, однако хочу отметить, что вам нужно во время термина выяснить причину, спросить, как он видит ваше развитие и чего, по его мнению, вам не хватает, чтобы получить финансирование. То есть важность термина с полным пониманием, какое решение принято и как можно на это повлиять, если потребуется. | DM4: Рекомендация | DN4: А) Психологический и демографический портрет Клиента: Клиент - Виктория, спокойная, не склонная к панике, как она сама говорит "всегда спокойная, готова к любым результатам". [00:04:06.980] Проявляет небольшое беспокойство по поводу запоминания информации к далекой дате термина и скорости работы Job Center. Уточняющая, задает вопросы по процессу. Не проявляет инициативу в поиске информации, но готова следовать рекомендациям.Б) Цели и приоритеты Клиента: Главная цель клиента - получить сертификат, который котируется в Германии. [00:08:34.520] Возможно, ищет стабильность и возможность трудоустройства в Германии. Страх потерять время зря или получить недействительный документ. Нет ярко выраженных болей или страхов, кроме общих беспокойств по поводу бюрократических процессов.В) Дополнительные характеристики и предложения:Для маркетинга: Использовать формулировки, подчеркивающие официальность, государственную поддержку и признание сертификата в Германии. Акцент на пошаговое сопровождение и снятие бюрократических сложностей.УТП, которые сработали бы сильнее: Гарантии официального признания сертификата, подробное объяснение всех этапов взаимодействия с Job Center и Agentur für Arbeit, поддержка в случае отказа.Фичи/бонусы/способы оплаты: Важно акцентировать на полном сопровождении до трудоустройства, включая помощь с резюме и собеседованиями.Сегмент/персона/рынок: Клиент не ищет "быстрых" решений, а ориентирован на легальность и официальность, что характерно для людей, переехавших в Германию и стремящихся к интеграции на рынок труда. Этот сегмент ценит надежность и понятные процессы, готовность к бюрократии, но нуждается в поддержке. | DO4: [00:04:06.980] – Клиент – Нет, я спокойная всегда, я готова к любым результатам, поэтому я не могу., [00:08:34.520] – Клиент – Нет, мне главное, чтобы сертификат котировался в Германии. | DP4: 1 | DQ4: Разговор был полноценным, завершился логично, участники попрощались. | DR4: [00:09:20.020] – Продавец – До свидания., [00:09:21.040] – Клиент – До свидания.. | DS4: 1 | DT4: Звонок относится к этапу первого контакта сопровождения. Признаки первого контакта включают: поздравление с назначенным термином, объяснение цели звонка как первичной подготовки, разговор о том, как проходит встреча с бератером, обещание отправить тренажер и договоренность о следующем контакте для дальнейшей подготовки.Все эти пункты были соблюдены. | DU4: [00:00:15.160] – Клиент – Да, сегодня удалось на 24 марта., [00:00:19.512] – Продавец – Я вас поздравляю. Подскажите, пожалуйста, есть ли у вас буквально 5-10 минут для того, чтобы мы дальнейшие шаги, например, обсудили, подготовку к термину?, [00:01:13.238] – Продавец – В любом случае, главное, что смысл встреч понимаете, какие вопросы будет бирайтер задавать..., [00:01:50.240] – Продавец – Я вам его тогда отправлю на e-mail., [00:02:45.380] – Продавец – Подскажите, пожалуйста, также могу с вами позвонить где-нибудь, например, 12-го числа, 13-го числа, для того, чтобы, если у вас появятся вопросы по памятке, либо вообще в целом, может быть, про обучение какие-то вопросы появятся, я на них отвечу, в какое время вам будет удобно? | DV4: =IFERROR(SUM(AC4,AF4)/COUNT(AC4,AF4),"Приветствие") -> Приветствие | DW4: =IFERROR(SUM(AI4,AL4)/COUNT(AI4,AL4),"Снятие первичного волнения") -> Снятие первичного волнения | DX4: =IFERROR(SUM(AO4,AR4,AU4)/COUNT(AO4,AR4,AU4),"Презентация предстоящего термина") -> Презентация предстоящего термина | DY4: =IFERROR(SUM(AX4,BA4,BD4)/COUNT(AX4,BA4,BD4),"Отправка материалов") -> Отправка материалов | DZ4: =IFERROR(SUM(BG4,BJ4,BM4)/COUNT(BG4,BJ4,BM4),"Вопросы и возражения Клиента") -> Вопросы и возражения Клиента | EA4: =IFERROR(SUM(BP4,BS4)/COUNT(BP4,BS4),"Следующие шаги") -> Следующие шаги | EB4: =IFERROR(SUM(BV4,BY4,CB4,CE4)/COUNT(BV4,BY4,CB4,CE4),"Завершение разговора") -> Завершение разговора | EC4: =IFERROR(SUM(CH4,CK4)/COUNT(CH4,CK4),"Стандарты общения") -> Стандарты общения | ED4: =IFERROR(SUM(CN4,CQ4,CT4)/COUNT(CN4,CQ4,CT4),"Критические ошибки") -> Критические ошибки | EE4: =IFERROR(SUM(#REF!,#REF!)/COUNT(#REF!,#REF!),"Экспертный блок") -> Экспертный блок | EF4: =IFERROR(SUM(#REF!,#REF!,#REF!,#REF!)/COUNT(#REF!,#REF!,#REF!,#REF!),"Рекомендации") -> Рекомендации | EG4: =IFERROR(SUM(#REF!,#REF!)/COUNT(#REF!,#REF!),"Фильтры") -> Фильтры | EH4: 0.92307692 | EI4: 0.875 | EJ4: 9.3924 | EK4: 1 | EL4: 1 | EM4: {=IFERROR( SUM(IF({AD4,AG4,AJ4,AM4,AP4,AS4,AV4,AY4,BB4,BE4,BK4,BN4,BQ4,BT4,BW4,BZ4,CC4,CF4,CI4,CL4}="",hidden!C4,{AD4,AG4,AJ4,AM4,AP4,AS4,AV4,AY4,BB4,BE4,BK4,BN4,BQ4,BT4,BW4,BZ4,CC4,CF4,CI4,CL4}+hidden!D4)) / COUNT(IF({AD4,AG4,AJ4,AM4,AP4,AS4,AV4,AY4,BB4,BE4,BK4,BN4,BQ4,BT4,BW4,BZ4,CC4,CF4,CI4,CL4}="",hidden!C4,{AD4,AG4,AJ4,AM4,AP4,AS4,AV4,AY4,BB4,BE4,BK4,BN4,BQ4,BT4,BW4,BZ4,CC4,CF4,CI4,CL4}+hidden!D4)) ,"")} -> 0.9 | EN4: =I4/hidden!A1 -> 9.3924
A5: 5 | B5: 195627662_1888425111_b89574 | C5: https://docs.google.com/document/d/1Pst-TCISMQXFmZEMYrmqtQcdR7F-wMwwL_D4cqn5iDg/edit?usp=drivesdk | D5: 2026-03-09 - 2026-03-15 | E5: 54740 | F5: 2026-03-11 15:00:20 | G5: 2026-03-11 15:10:31 | H5: 2026.03 | I5: 861.624 | J5: 1 | K5: 2026-03-11 | L5: 862 | M5: 195627662_1888425111 | N5: +491606896909, Статус: Разговор состоялся | O5: CallGear | P5: 11:35:40+01:00 | Q5: Исходящий | R5: 11 | S5: 14900444 | T5: Hanna Bielokon | U5: Контакт | V5: 2026-03-11T11:31:07+01:00 | W5: 18379056 | X5: Автосделка: Lead from: https://sternmeister.de/education?utm_source=facebook&utm_medium=video_diana_gipnoz&utm_id=lp_short&utm_campaign=%7Ccntry%3DGermany%7Creg%3Dall%7Cgls%3Dqual_lead%7Caid%7C120225303723160678&utm_content=cid%7C120224919600550678%7Cgid% | Y5: Бух Бератер | Z5: Принято от первой линии | AA5: https://sternmeister.kommo.com/leads/detail/18379056 | AB5: 14817967 | AC5: Кристина Никоненко | AD5: 1 | AE5: Менеджер поприветствовала клиента, представилась и обозначила название компании. Это соответствует критерию: приветствие было вежливым, менеджер назвала себя Кристиной и уточнила название компании Штернмастер. | AF5: [00:00:04.334] – Продавец – Здравствуйте, меня зовут Кристина, я менеджер сопровождения компании Штернмастер. | AG5: 1 | AH5: Менеджер кратко объяснила цель звонка — обсудить дальнейшие шаги перед термином, обозначила примерную длительность разговора (5-10 минут) и уточнила, удобно ли клиенту сейчас говорить. Это полностью отвечает критерию. | AI5: [00:00:12.907] – Продавец – Подскажите, пожалуйста, есть ли у вас буквально 5-10 минут для того, чтобы мы обсудили дальнейшие шаги перед термином? | AJ5: 0 | AK5: Менеджер не спросила напрямую о волнении клиента или его самочувствии перед термином. Вопросы и поддержка были связаны с процессом, но прямого уточнения эмоционального состояния не было. | AM5: 1 | AN5: Клиент была немного обеспокоена процессом (например из-за новой земли, экзаменов и статуса), и менеджер выразила поддержку, при этом попыталась снизить волнение, заверив в своей поддержке перед термином и мотивируя, что всё получится. | AO5: [00:00:43.070] – Продавец – Ну, значит, нужно себя хорошо презентовать ему., [00:00:49.778] – Продавец – Моя задача помочь вам подготовиться, ответить на все вопросы и сделать так, чтобы вы пришли на встречу с берайтером спокойно, уверенно. | AP5: 1 | AQ5: Менеджер объяснила, что встреча нужна для проверки мотивации и понимания курса, а также упомянула роль берайтера. По формату встречи она указала, что берайтер будет задавать вопросы о курсе, мотивации, и конечной целью должно быть трудоустройство. | AR5: [00:05:35.944] – Продавец – Ну, в принципе, вы знаете уже, да, как встреча с берайтером проходит по поводу обучения., [00:05:49.444] – Продавец – чтобы берайтер понимал, что, конечно, ваша финальная точка будет трудоустройство. | AS5: 1 | AT5: Менеджер привела примеры типичных вопросов: почему выбрали бухгалтерию, какой курс, что есть в курсе, финальная цель — трудоустройство. Это отвечает критерию. | AU5: [00:05:39.488] – Продавец – Это вопрос про вашу мотивацию, почему вы брали именно бухгалтерию, что за курс, какой курс, да, там, что есть в этом курсе, да, и чтобы берайтер понимал, что, конечно, ваша финальная точка будет трудоустройство. | AV5: 1 | AW5: Менеджер неоднократно поддерживала клиента, говорила, что не нужно бояться отвечать простыми фразами, отмечала, что главное — стратегия ответов и понимание логики, и что уровень немецкого уже хороший. Это снижает страх перед термином. | AX5: [00:06:15.279] – Продавец – От слова идет на уровень простыми фразами, но тут главное понять логику, как и что отвечать берайтеру, в каком варианте ответ, соответственно, на немецком языке., [00:08:29.199] – Продавец – Он будет у меня хороший, господи, этот уровень языка., [00:08:37.990] – Продавец – И то, что вы добились уже сейчас хороших результатов, это только ваша заслуга, ваше стремление и желание. | AY5: 1 | AZ5: Менеджер прямо сообщила, что отправит памятку по подготовке к термину. О канале отправки сказано, что 'в любом случае напишет в WhatsApp', что подразумевает отправку памятки тоже этим каналом. | BA5: [00:06:11.014] – Продавец – Я вам отправлю на всякий случай памятку, подготовку к терминам., [00:10:42.268] – Продавец – Еще в WhatsApp обязательно. | BB5: 1 | BC5: Менеджер объяснила, что в памятке: список типичных фраз, логика ответов берайтеру, типичные ловушки, правильная стратегия ответов — что поможет подготовиться к встрече. | BD5: [00:06:14.098] – Продавец – Это такой костыль. От слова идет на уровень простыми фразами, но тут главное понять логику, как и что отвечать берайтеру, в каком варианте ответ, соответственно, на немецком языке., [00:06:25.000] – Продавец – Там есть фразы типичные ловушки от берайтера, правильная стратегия ответов. | BE5: 1 | BF5: Менеджер сообщила о тренажёре и разъяснила его назначение — для отработки ответов от имени берайтера, аналог бота-тренажёра. | BG5: [00:08:14.641] – Продавец – И также отправлю вам этот пятичат-бот. Он задает вопросы от имени берайтера и сможете проговорить как раз-таки ответы. | BH5: Тегов нет | BI5: В течение разговора клиент проявлял ряд опасений и сомнений, среди которых: Страх отказа в финансировании (финансы семьи, смена статуса), Сомнение в курсе (нет опыта бухгалтера), Недостаточная подготовка (уровень немецкого, практика). | BJ5: [00:01:43.289] – Клиент – Я надеюсь на то, что это уже будет в новой земле, правильно понимаю?, [00:03:44.349] – Клиент – Скажут ли мне сейчас, что, фрау, не многовато ли обучения?, [00:07:46.310] – Клиент – И если сумма подходит под программу, то одобрение, случайно, возможно?, [00:11:33.852] – Клиент – Не пожалею ли я, что я без опыта вообще макнулась в это дело, и мне не хватит просто понимания процессов, не то что языка. | BK5: 1 | BL5: Менеджер корректно реагировала на озвученные опасения (финансы, опыт, подготовка): подробно объясняла процесс, снижала волнение и поддерживала клиента. | BM5: [00:05:56.915] – Продавец – Я вам... Ну, ранее вы проходили... А как давно проходили на лучшей?, [00:08:37.990] – Продавец – И то, что вы добились уже сейчас хороших результатов, это только ваша заслуга, ваше стремление и желание., [00:12:35.609] – Продавец – Здесь с нуля спокойно обучаются, потому что материалы программы охватывают. ... Тут разберется любой. | BN5: 1 | BO5: Клиент задавала комплексные вопросы по поводу процесса финансирования, формальностей, курса бухгалтерии и необходимости опыта. Менеджер дала исчерпывающие и понятные ответы на все вопросы. | BP5: [00:01:50.659] – Клиент – Я надеюсь на то, что это уже будет в новой земле, правильно понимаю? — [00:01:50.659] – Продавец – Да, это будет уже в новой земле., [00:11:16.004] – Клиент – У меня 17 лет было свое частное предприятие...., [00:12:15.515] – Клиент – Это я поняла, это с нуля материал? — [00:12:19.302] – Продавец – Да. | BQ5: 1 | BR5: Менеджер согласовала следующий контакт на 15 или 16 число, с объяснением даты и цели контакта (подготовка к встрече с берайтером и уточнение деталей после консультации с другом супруга, бывшим сотрудником Jobcenter). | BS5: [00:09:48.614] – Продавец – Он ранее тоже работал в джоб-центре и подготовит вас к встрече с берайтером в агентуре Фарбайки., [00:10:08.057] – Продавец – Или даже давайте в воскресенье, 15-го числа. Будет еще лучше. | BT5: 1 | BU5: Менеджер указала, что будет на связи с клиентом на всём этапе до термина и что коллега напишет в WhatsApp, создавая ощущение открытого взаимодействия. | BV5: [00:00:47.034] – Продавец – И я буду с вами на связи до самого дня термина., [00:10:37.379] – Продавец – Она вам в любом случае напишет в WhatsApp. | BW5: 0 | BX5: Менеджер не уточнила в явной форме, стало ли клиенту понятнее и увереннее после разговора, не задала вопрос о текущем состоянии клиента после консультации. | BZ5: 1 | CA5: Менеджер объясняла про дальнейший процесс (например, получения документов после прохождения термина), а также консультирование с коллегой после прохождения. | CB5: [00:09:19.746] – Продавец – Также хотелось бы поговорить важный момент, если термин в джоб-центре пройдет успешно, ваши документы также придут., [00:09:25.316] – Продавец – У вас будет в агентуре термин или в джоб-центре? | CC5: 0 | CD5: Менеджер не объяснила, что делать в случае отказа в финансировании и как себя вести при неудаче с берайтером. | CF5: 1 | CG5: Менеджер указала, что после консультации с другом будет следующий контакт (разбор с ведущим специалистом до и после термина), создав иллюзию постоянного сопровождения. | CH5: [00:10:31.368] – Продавец – Она вам в любом случае напишет в WhatsApp., [00:11:02.604] – Продавец – У нас уже будет полная картина, как действовать дальше. | CI5: 1 | CJ5: Менеджер неоднократно обращалась к клиенту по имени, использовала вежливые слова (спасибо, пожалуйста, поздравляю, хорошо), вела разговор искренне, доброжелательно, с поддержкой и похвалой (даже с самооценочной поддержкой), имела позитивный тон. | CK5: [00:00:26.469] – Продавец – Хорошо, поздравляю вас с ремонтом., [00:08:29.199] – Продавец – Он будет у меня хороший, господи, этот уровень языка., [00:08:59.115] – Продавец – Ты с ума сошла, надо себя хвалить. | CL5: 1 | CM5: Менеджер многократно показывала, что слушает и понимает клиента, перефразировала вопросы, поддерживала прямой диалог (например, по финансовому статусу, смене статуса, вопросам экзамена). Темп был живым, много реплик поддержки и перефразирования. | CN5: [00:01:50.659] – Продавец – Да, это будет уже в новой земле., [00:05:07.636] – Продавец – Вижу, что вам нужно еще сдать на права., [00:12:01.216] – Продавец – Ваш вопрос. Хочу отметить, что мы не готовим теоретиков... | CO5: 1 | CP5: Ни одной критической ошибки, вредной для компании, не зафиксировано. Диалог вёлся уважительно, следующие шаги зафиксированы, не было введения в заблуждение, отказа от клиента или некорректного обсуждения лицензий/процессов. | CR5: 1 | CS5: В разговоре не было ни грубости, ни дезинформации, ни агрессии. Информация про курс соответствовала действительности, никакой ложной или опасной информации не прозвучало. | CU5: 1 | CV5: Менеджер не давала ложных обещаний (например, гарантии трудоустройства), не разглашала внутреннюю конфиденциальную информацию, не вводила в заблуждение относительно AZAV/сертификата и в целом соблюдала допустимые рамки коммуникации. | CX5: 1 | CY5: А) Продавец начал с приветствия, представления и поздравления клиента, далее уточнил удобство разговора, объяснил цель диалога. Затем последовательно обсуждался статус клиента (экзамены, новый берайтер, смена земли), далее проговаривались детали финансирования, возможных сложностей, затем был дан обзор формата встречи с берайтером и курса, отправка памятки, договорённость о следующем контакте. Б) Особенность: продавец много слушал, адаптировался под клиента, приводил конкретные советы. В) У клиента появился интерес, он задал ряд вопросов, открылся и делился деталями ситуации. Г) Клиент не ушёл в сомнение, но не было финального вопроса по уверенности/готовности. | CZ5: [00:00:04.334] – Продавец – Здравствуйте, меня зовут Кристина, я менеджер сопровождения компании Штернмастер., [00:06:11.014] – Продавец – Я вам отправлю на всякий случай памятку, подготовку к терминам., [00:10:08.057] – Продавец – Или даже давайте в воскресенье, 15-го числа. | DA5: 1 | DB5: Разговор завершился позитивно, клиент согласилась на дальнейший контакт (дата обсуждена), материалы согласованы. Продавец корректно довёл до фиксации следующего шага. | DC5: [00:10:31.368] – Продавец – Она вам в любом случае напишет в WhatsApp., [00:14:13.961] – Продавец – Ну, хорошо, вам удачного, доброго дня. | DD5: Резюме | DE5: А) Темы звонка: приветствие, поздравление с термином, обсуждение текущей ситуации (экзамены, переезд, смена статуса), детали финансирования, обсуждение возможных сложностей, объяснение формата встречи с берайтером, отправка памятки, обсуждение курса и этапов, договорённость о следующем контакте. Б) Реакция клиента: заинтересованная, иногда озабоченная (финансы, статус), охотно делилась деталями и задавала вопросы, проявляла интерес к курсу, но также открыто обсуждала страхи и неопределённость. В) Зафиксировано: отправка памятки и тренажёра, обсуждение даты следующего созвона (15-16 числа), согласие на продолжение диалога, обмен контактами. | DG5: Рекомендация | DH5: 1. Не уточнено прямо эмоциональное состояние/уровень понятности после консультации. Лучше спросить: 'Анна, стало ли вам спокойнее после разговора? Всё ли теперь понятно про встречу с берайтером?' — Это снизит тревожность и повысит доверие. 2. Не озвучены шаги на случай отказа берайтера в финансировании. Рекомендация: 'Если вдруг получите отказ, обязательно узнаете причину и дайте знать нам, мы поможем подготовить обоснование.' — Это уменьшает страх отказа. 3. Можно было бы чуть подробнее дать вводный обзор по формату курса и преимуществам именно Sternmeister, чтобы усилить мотивацию и УТП. Пример: 'Наш курс выделяется тем, что...'. Ожидаемый эффект — рост уверенности и доверия клиента на старте. | DJ5: Рекомендация | DK5: 1. Поддержка и похвала клиента — 'И то, что вы добились уже сейчас хороших результатов, это только ваша заслуга...' — укрепляет доверие и позитивное отношение, массовая техника. 2. Персонализированный подход с учётом индивидуальных сложностей клиента (семья, статус, экзамены) — пример адаптации под клиента, индивидуальная техника. 3. Чёткость и структурность в доведении до следующего шага — фиксация даты следующего контакта и открытый канал в WhatsApp. Это массовая практика управления ожиданиями. | DM5: Рекомендация | DN5: А) Психологический и демографический портрет: Женщина, имя Анна, переехала в Германию, недавно вышла замуж, опыт работы воспитателем и предпринимателем, ответственный и тревожный стиль принятия решений, склонна к сомнениям (страх отказа, недостаточная подготовка), проявляет инициативу в уточнениях ('А мне Оля сейчас выслала'). Б) Цели: интеграция в немецкий рынок, смена профессии ('Я, в принципе, не бухгалтер...'), получение финансирования, уверенность в будущем ('Я шла по этому пути, потому что пыталась остаться в Мангелисте'). Переживает о фин. критериях, статусе в джоб-центре. В) Для маркетинга: важно подчеркивать поддержку на всех этапах, пошаговую структуру курса, простоту материала, возможность стартовать с нуля, организацию сопровождения по смене статуса. Для таких клиентов нужны подробные инструкции, список типовых ошибок и частые контакты. Каналы: WhatsApp, email, много практики в курсе, реальные кейсы. | DP5: 1 | DQ5: Разговор завершился естественно, участники попрощались, диалог был полноразмерным, технических сбоев не было. | DR5: [00:14:13.961] – Продавец – Ну, хорошо, вам удачного, доброго дня., [00:14:18.894] – Клиент – До свидания. | DS5: 1 | DT5: Это первый контакт сопровождения — менеджер поздравила с термином, обозначила себя как куратора до дня встречи, впервые подробно рассказала о формате термина, отправила памятку и договорилась о подготовке. Нет тематики промежуточной или финального контакта. | DU5: [00:00:09.021] – Продавец – Поздравляю вас с назначенным термином., [00:00:47.034] – Продавец – И я буду с вами на связи до самого дня термина., [00:06:11.014] – Продавец – Я вам отправлю на всякий случай памятку, подготовку к терминам., [00:10:08.057] – Продавец – Или даже давайте в воскресенье, 15-го числа. | DV5: =IFERROR(SUM(AC5,AF5)/COUNT(AC5,AF5),"Приветствие") -> Приветствие | DW5: =IFERROR(SUM(AI5,AL5)/COUNT(AI5,AL5),"Снятие первичного волнения") -> Снятие первичного волнения | DX5: =IFERROR(SUM(AO5,AR5,AU5)/COUNT(AO5,AR5,AU5),"Презентация предстоящего термина") -> Презентация предстоящего термина | DY5: =IFERROR(SUM(AX5,BA5,BD5)/COUNT(AX5,BA5,BD5),"Отправка материалов") -> Отправка материалов | DZ5: =IFERROR(SUM(BG5,BJ5,BM5)/COUNT(BG5,BJ5,BM5),"Вопросы и возражения Клиента") -> Вопросы и возражения Клиента | EA5: =IFERROR(SUM(BP5,BS5)/COUNT(BP5,BS5),"Следующие шаги") -> Следующие шаги | EB5: =IFERROR(SUM(BV5,BY5,CB5,CE5)/COUNT(BV5,BY5,CB5,CE5),"Завершение разговора") -> Завершение разговора | EC5: =IFERROR(SUM(CH5,CK5)/COUNT(CH5,CK5),"Стандарты общения") -> Стандарты общения | ED5: =IFERROR(SUM(CN5,CQ5,CT5)/COUNT(CN5,CQ5,CT5),"Критические ошибки") -> Критические ошибки | EE5: =IFERROR(SUM(#REF!,#REF!)/COUNT(#REF!,#REF!),"Экспертный блок") -> Экспертный блок | EF5: =IFERROR(SUM(#REF!,#REF!,#REF!,#REF!)/COUNT(#REF!,#REF!,#REF!,#REF!),"Рекомендации") -> Рекомендации | EG5: =IFERROR(SUM(#REF!,#REF!)/COUNT(#REF!,#REF!),"Фильтры") -> Фильтры | EH5: 0.88888889 | EI5: 0.8125 | EJ5: 14.3604 | EK5: 1 | EL5: 1 | EM5: {=IFERROR( SUM(IF({AD5,AG5,AJ5,AM5,AP5,AS5,AV5,AY5,BB5,BE5,BK5,BN5,BQ5,BT5,BW5,BZ5,CC5,CF5,CI5,CL5}="",hidden!C5,{AD5,AG5,AJ5,AM5,AP5,AS5,AV5,AY5,BB5,BE5,BK5,BN5,BQ5,BT5,BW5,BZ5,CC5,CF5,CI5,CL5}+hidden!D5)) / COUNT(IF({AD5,AG5,AJ5,AM5,AP5,AS5,AV5,AY5,BB5,BE5,BK5,BN5,BQ5,BT5,BW5,BZ5,CC5,CF5,CI5,CL5}="",hidden!C5,{AD5,AG5,AJ5,AM5,AP5,AS5,AV5,AY5,BB5,BE5,BK5,BN5,BQ5,BT5,BW5,BZ5,CC5,CF5,CI5,CL5}+hidden!D5)) ,"")} -> 0.85 | EN5: =I5/hidden!A2 -> 14.3604
